<?xml version="1.0" ?>
<robot name="Wheel_Legged_Robot" xmlns:xacro="http://www.ros.org/wiki/xacro">

<xacro:include filename="$(find Wheel_Legged_Robot_description)/urdf/materials.xacro" />
<xacro:include filename="$(find Wheel_Legged_Robot_description)/urdf/Wheel_Legged_Robot.trans" />
<xacro:include filename="$(find Wheel_Legged_Robot_description)/urdf/Wheel_Legged_Robot.gazebo" />
<link name="base_link">
  <inertial>
    <origin xyz="7.278755555595769e-05 6.853301093091262e-05 0.10454006040928629" rpy="0 0 0"/>
    <mass value="2.766871284084967"/>
    <inertia ixx="0.037283" iyy="0.02581" izz="0.054249" ixy="2.5e-05" iyz="-3.6e-05" ixz="-3e-06"/>
  </inertial>
  <visual>
    <origin xyz="0 0 0" rpy="0 0 0"/>
    <geometry>
      <mesh filename="package://Wheel_Legged_Robot_description/meshes/base_link.stl" scale="0.001 0.001 0.001"/>
    </geometry>
    <material name="silver"/>
  </visual>
  <collision>
    <origin xyz="0 0 0" rpy="0 0 0"/>
    <geometry>
      <mesh filename="package://Wheel_Legged_Robot_description/meshes/base_link.stl" scale="0.001 0.001 0.001"/>
    </geometry>
  </collision>
</link>

<link name="Drive_Link_4">
  <inertial>
    <origin xyz="-0.040657247217053535 0.011647443353258069 3.941291737419306e-15" rpy="0 0 0"/>
    <mass value="0.11059196165017098"/>
    <inertia ixx="3.1e-05" iyy="0.000376" izz="0.000359" ixy="1.1e-05" iyz="-0.0" ixz="-0.0"/>
  </inertial>
  <visual>
    <origin xyz="0.075 -0.147 -0.1104" rpy="0 0 0"/>
    <geometry>
      <mesh filename="package://Wheel_Legged_Robot_description/meshes/Drive_Link_4.stl" scale="0.001 0.001 0.001"/>
    </geometry>
    <material name="silver"/>
  </visual>
  <collision>
    <origin xyz="0.075 -0.147 -0.1104" rpy="0 0 0"/>
    <geometry>
      <mesh filename="package://Wheel_Legged_Robot_description/meshes/Drive_Link_4.stl" scale="0.001 0.001 0.001"/>
    </geometry>
  </collision>
</link>

<link name="Drive_Link_1">
  <inertial>
    <origin xyz="0.04065724721705395 0.01164744335325793 -5.9396931817445875e-15" rpy="0 0 0"/>
    <mass value="0.11059196165017098"/>
    <inertia ixx="3.1e-05" iyy="0.000376" izz="0.000359" ixy="-1.1e-05" iyz="0.0" ixz="-0.0"/>
  </inertial>
  <visual>
    <origin xyz="-0.075 -0.147 -0.1104" rpy="0 0 0"/>
    <geometry>
      <mesh filename="package://Wheel_Legged_Robot_description/meshes/Drive_Link_1.stl" scale="0.001 0.001 0.001"/>
    </geometry>
    <material name="silver"/>
  </visual>
  <collision>
    <origin xyz="-0.075 -0.147 -0.1104" rpy="0 0 0"/>
    <geometry>
      <mesh filename="package://Wheel_Legged_Robot_description/meshes/Drive_Link_1.stl" scale="0.001 0.001 0.001"/>
    </geometry>
  </collision>
</link>

<link name="Drive_Link_2">
  <inertial>
    <origin xyz="-0.040657247217053244 -0.011647443353256959 -6.938893903907228e-15" rpy="0 0 0"/>
    <mass value="0.11059196165017098"/>
    <inertia ixx="3.1e-05" iyy="0.000376" izz="0.000359" ixy="-1.1e-05" iyz="-0.0" ixz="0.0"/>
  </inertial>
  <visual>
    <origin xyz="0.075 0.147 -0.1104" rpy="0 0 0"/>
    <geometry>
      <mesh filename="package://Wheel_Legged_Robot_description/meshes/Drive_Link_2.stl" scale="0.001 0.001 0.001"/>
    </geometry>
    <material name="silver"/>
  </visual>
  <collision>
    <origin xyz="0.075 0.147 -0.1104" rpy="0 0 0"/>
    <geometry>
      <mesh filename="package://Wheel_Legged_Robot_description/meshes/Drive_Link_2.stl" scale="0.001 0.001 0.001"/>
    </geometry>
  </collision>
</link>

<link name="Drive_Link_3">
  <inertial>
    <origin xyz="0.040657247217054424 -0.011647443353257042 2.886579864025407e-15" rpy="0 0 0"/>
    <mass value="0.11059196165017098"/>
    <inertia ixx="3.1e-05" iyy="0.000376" izz="0.000359" ixy="1.1e-05" iyz="0.0" ixz="0.0"/>
  </inertial>
  <visual>
    <origin xyz="-0.075 0.147 -0.1104" rpy="0 0 0"/>
    <geometry>
      <mesh filename="package://Wheel_Legged_Robot_description/meshes/Drive_Link_3.stl" scale="0.001 0.001 0.001"/>
    </geometry>
    <material name="silver"/>
  </visual>
  <collision>
    <origin xyz="-0.075 0.147 -0.1104" rpy="0 0 0"/>
    <geometry>
      <mesh filename="package://Wheel_Legged_Robot_description/meshes/Drive_Link_3.stl" scale="0.001 0.001 0.001"/>
    </geometry>
  </collision>
</link>

<link name="Motor_Link_1">
  <inertial>
    <origin xyz="0.13428899038332048 -0.008913491097867293 -0.08895579338810648" rpy="0 0 0"/>
    <mass value="0.14032213696340154"/>
    <inertia ixx="0.0004" iyy="0.001297" izz="0.000903" ixy="-1e-06" iyz="1e-06" ixz="0.000537"/>
  </inertial>
  <visual>
    <origin xyz="0.225 0.17 -0.1104" rpy="0 0 0"/>
    <geometry>
      <mesh filename="package://Wheel_Legged_Robot_description/meshes/Motor_Link_1.stl" scale="0.001 0.001 0.001"/>
    </geometry>
    <material name="silver"/>
  </visual>
  <collision>
    <origin xyz="0.225 0.17 -0.1104" rpy="0 0 0"/>
    <geometry>
      <mesh filename="package://Wheel_Legged_Robot_description/meshes/Motor_Link_1.stl" scale="0.001 0.001 0.001"/>
    </geometry>
  </collision>
</link>

<link name="Wheel_Tire_1">
  <inertial>
    <origin xyz="0.00012421328762900045 -0.021574487388235725 0.0002810100437786525" rpy="0 0 0"/>
    <mass value="0.5016895329855149"/>
    <inertia ixx="0.000813" iyy="0.00129" izz="0.000809" ixy="1e-06" iyz="2e-06" ixz="-2e-06"/>
  </inertial>
  <visual>
    <origin xyz="-0.000685 0.185 0.044491" rpy="0 0 0"/>
    <geometry>
      <mesh filename="package://Wheel_Legged_Robot_description/meshes/Wheel_Tire_1.stl" scale="0.001 0.001 0.001"/>
    </geometry>
    <material name="silver"/>
  </visual>
  <collision>
    <origin xyz="-0.000685 0.185 0.044491" rpy="0 0 0"/>
    <geometry>
      <mesh filename="package://Wheel_Legged_Robot_description/meshes/Wheel_Tire_1.stl" scale="0.001 0.001 0.001"/>
    </geometry>
  </collision>
</link>

<link name="Motor_Link_2">
  <inertial>
    <origin xyz="-0.13428899038331973 0.008913491097868015 -0.08895579338810554" rpy="0 0 0"/>
    <mass value="0.14032213696340154"/>
    <inertia ixx="0.0004" iyy="0.001297" izz="0.000903" ixy="-1e-06" iyz="-1e-06" ixz="-0.000537"/>
  </inertial>
  <visual>
    <origin xyz="-0.225 -0.17 -0.1104" rpy="0 0 0"/>
    <geometry>
      <mesh filename="package://Wheel_Legged_Robot_description/meshes/Motor_Link_2.stl" scale="0.001 0.001 0.001"/>
    </geometry>
    <material name="silver"/>
  </visual>
  <collision>
    <origin xyz="-0.225 -0.17 -0.1104" rpy="0 0 0"/>
    <geometry>
      <mesh filename="package://Wheel_Legged_Robot_description/meshes/Motor_Link_2.stl" scale="0.001 0.001 0.001"/>
    </geometry>
  </collision>
</link>

<link name="Wheel_Tire_2">
  <inertial>
    <origin xyz="0.00012365184449981428 0.021574487388236585 -0.0002805722170579131" rpy="0 0 0"/>
    <mass value="0.5016895329855149"/>
    <inertia ixx="0.000813" iyy="0.00129" izz="0.000809" ixy="-1e-06" iyz="2e-06" ixz="2e-06"/>
  </inertial>
  <visual>
    <origin xyz="0.000685 -0.185 0.044491" rpy="0 0 0"/>
    <geometry>
      <mesh filename="package://Wheel_Legged_Robot_description/meshes/Wheel_Tire_2.stl" scale="0.001 0.001 0.001"/>
    </geometry>
    <material name="silver"/>
  </visual>
  <collision>
    <origin xyz="0.000685 -0.185 0.044491" rpy="0 0 0"/>
    <geometry>
      <mesh filename="package://Wheel_Legged_Robot_description/meshes/Wheel_Tire_2.stl" scale="0.001 0.001 0.001"/>
    </geometry>
  </collision>
</link>

<joint name="Left_Rear_Drive" type="continuous">
  <origin xyz="-0.075 0.147 0.1104" rpy="0 0 0"/>
  <parent link="base_link"/>
  <child link="Drive_Link_4"/>
  <axis xyz="0.0 1.0 0.0"/>
</joint>

<joint name="Left_Front_Drive" type="continuous">
  <origin xyz="0.075 0.147 0.1104" rpy="0 0 0"/>
  <parent link="base_link"/>
  <child link="Drive_Link_1"/>
  <axis xyz="0.0 1.0 0.0"/>
</joint>

<joint name="Right_Rear_Drive" type="continuous">
  <origin xyz="-0.075 -0.147 0.1104" rpy="0 0 0"/>
  <parent link="base_link"/>
  <child link="Drive_Link_2"/>
  <axis xyz="-0.0 -1.0 -0.0"/>
</joint>

<joint name="Right_Front_Drive" type="continuous">
  <origin xyz="0.075 -0.147 0.1104" rpy="0 0 0"/>
  <parent link="base_link"/>
  <child link="Drive_Link_3"/>
  <axis xyz="-0.0 -1.0 -0.0"/>
</joint>

<joint name="Right_1" type="continuous">
  <origin xyz="-0.15 -0.023 0.0" rpy="0 0 0"/>
  <parent link="Drive_Link_2"/>
  <child link="Motor_Link_1"/>
  <axis xyz="0.0 1.0 0.0"/>
</joint>

<joint name="Right_Wheel" type="continuous">
  <origin xyz="0.225685 -0.015 -0.154891" rpy="0 0 0"/>
  <parent link="Motor_Link_1"/>
  <child link="Wheel_Tire_1"/>
  <axis xyz="-0.0 -1.0 -0.0"/>
</joint>

<joint name="Left_1" type="continuous">
  <origin xyz="0.15 0.023 0.0" rpy="0 0 0"/>
  <parent link="Drive_Link_1"/>
  <child link="Motor_Link_2"/>
  <axis xyz="0.0 1.0 0.0"/>
</joint>

<joint name="Left_Wheel" type="continuous">
  <origin xyz="-0.225685 0.015 -0.154891" rpy="0 0 0"/>
  <parent link="Motor_Link_2"/>
  <child link="Wheel_Tire_2"/>
  <axis xyz="0.0 1.0 0.0"/>
</joint>

</robot>
